Workbook

Sheet Instructions
B2: Pharmaceutical Supply Chain & Inventory Management
B3: A working Excel model: EOQ, Safety Stock, Reorder Point, ABC Analysis, Expiry Tracking & Dashboard
B5: Workbook structure
B6: Product Master | C6: 30 SKUs across 11 therapeutic categories with supplier, cost, price, current stock, lead time, ordering cost and holding cost. This is the master input sheet — blue text marks editable inputs.
B7: Monthly Demand | C7: 12 months of unit demand per SKU (sample sales/dispensing history). Editable input sheet.
B8: Inventory Analysis | C8: The calculation engine. Pulls from the two sheets above via INDEX/MATCH and computes EOQ, Safety Stock, Reorder Point, ABC class and stock status automatically.
B9: Expiry Tracker | C9: Batch-level manufacture/expiry dates, used to flag near-expiry and expired stock — critical in pharma because expired inventory cannot be sold.
B10: Dashboard | C10: KPIs and charts summarizing inventory value, stock health, ABC mix and demand trend.
B12: Key formulas used
B13: Economic Order Quantity (EOQ) | C13: EOQ = SQRT( 2 x Annual Demand x Ordering Cost / Holding Cost per Unit ) — the order quantity that minimizes total ordering + holding cost.
B14: Holding Cost per Unit | C14: Unit Cost x Annual Holding Cost % (storage, insurance, spoilage/cold-chain risk, capital cost).
B15: Safety Stock | C15: Z x StdDev(Monthly Demand) x SQRT(Lead Time in days / 30) — buffer stock for demand variability during lead time. Z = 1.65 for ~95% service level.
B16: Reorder Point (ROP) | C16: (Average Daily Demand x Lead Time in days) + Safety Stock — the stock level that triggers a new purchase order.
B17: ABC Analysis | C17: SKUs ranked by Annual Consumption Value; cumulative % of value used to bucket items into A (top ~70% of value), B (next ~20%) and C (remaining ~10%), following the Pareto principle.
B18: Stock Status | C18: Flags 'Reorder Now' when Current Stock < Reorder Point, and 'Overstock' when Current Stock exceeds 2x EOQ.
B19: Expiry Status | C19: 'Expired' if past expiry date, 'Expiring Soon' if within 90 days, else 'OK'. Dates are date-driven (TODAY()), so this updates automatically each time you open the file.
B21: How to use / extend this
B22: Update data | C22: Edit blue cells in Product Master, Monthly Demand and Expiry Tracker with your real data — every formula downstream recalculates automatically.
B23: Change service level | C23: Adjust the Z-value in Inventory Analysis (currently hardcoded as 1.65) to raise/lower safety stock — use 1.28 for 90%, 1.65 for 95%, 2.33 for 99% service level.
B24: Add new SKUs | C24: Insert a new row in Product Master and Monthly Demand with the same SKU ID, then copy the formula row down in Inventory Analysis.
B25: Color legend | C25: Blue text = input cell you can edit. Black text = formula (do not overtype). Sheet tab colors match this legend.

Sheet Dashboard
A1: Pharmaceutical Inventory Management Dashboard
A2: Live KPIs computed from Product Master, Inventory Analysis & Expiry Tracker
A4: Total Active SKUs | B4: Total Inventory Value ($) | C4: Items Needing Reorder | D4: Overstocked Items | E4: Batches Expiring Soon (≤90d) | F4: Expired Batches
A5: =COUNTA('Product Master'!A2:A31) -> 30 | B5: =SUM('Inventory Analysis'!Q5:Q34) -> 37354.5 | C5: =COUNTIF('Inventory Analysis'!V5:V34,"Reorder Now") -> 5 | D5: =COUNTIF('Inventory Analysis'!V5:V34,"Overstock") -> 4 | E5: =COUNTIF('Expiry Tracker'!H2:H41,"Expiring Soon") -> 3 | F5: =COUNTIF('Expiry Tracker'!H2:H41,"Expired") -> 2
A8: Category | B8: Inventory Value ($) | D8: ABC Class | E8: SKU Count
A9: Analgesics | B9: =SUMIF('Inventory Analysis'!$C$5:$C$34,A9,'Inventory Analysis'!$Q$5:$Q$34) -> 1259.003 | D9: Class A | E9: =COUNTIF('Inventory Analysis'!$U$5:$U$34,"A") -> 7
A10: Antibiotics | B10: =SUMIF('Inventory Analysis'!$C$5:$C$34,A10,'Inventory Analysis'!$Q$5:$Q$34) -> 6116.605 | D10: Class B | E10: =COUNTIF('Inventory Analysis'!$U$5:$U$34,"B") -> 7
A11: Antidiabetics | B11: =SUMIF('Inventory Analysis'!$C$5:$C$34,A11,'Inventory Analysis'!$Q$5:$Q$34) -> 8125.41 | D11: Class C | E11: =COUNTIF('Inventory Analysis'!$U$5:$U$34,"C") -> 16
A12: Antihypertensives | B12: =SUMIF('Inventory Analysis'!$C$5:$C$34,A12,'Inventory Analysis'!$Q$5:$Q$34) -> 239.483
A13: Antivirals | B13: =SUMIF('Inventory Analysis'!$C$5:$C$34,A13,'Inventory Analysis'!$Q$5:$Q$34) -> 8072.884
A14: Cardiovascular | B14: =SUMIF('Inventory Analysis'!$C$5:$C$34,A14,'Inventory Analysis'!$Q$5:$Q$34) -> 1041.619 | D14: Stock Status | E14: SKU Count
A15: Dermatological | B15: =SUMIF('Inventory Analysis'!$C$5:$C$34,A15,'Inventory Analysis'!$Q$5:$Q$34) -> 924.768 | D15: OK | E15: =COUNTIF('Inventory Analysis'!$V$5:$V$34,"OK") -> 21
A16: Gastrointestinal | B16: =SUMIF('Inventory Analysis'!$C$5:$C$34,A16,'Inventory Analysis'!$Q$5:$Q$34) -> 1897.368 | D16: Reorder Now | E16: =COUNTIF('Inventory Analysis'!$V$5:$V$34,"Reorder Now") -> 5
A17: Respiratory | B17: =SUMIF('Inventory Analysis'!$C$5:$C$34,A17,'Inventory Analysis'!$Q$5:$Q$34) -> 2247.581 | D17: Overstock | E17: =COUNTIF('Inventory Analysis'!$V$5:$V$34,"Overstock") -> 4
A18: Vaccines | B18: =SUMIF('Inventory Analysis'!$C$5:$C$34,A18,'Inventory Analysis'!$Q$5:$Q$34) -> 6249.69
A19: Vitamins & Supplements | B19: =SUMIF('Inventory Analysis'!$C$5:$C$34,A19,'Inventory Analysis'!$Q$5:$Q$34) -> 1180.089
A22: Month | B22: Total Units Demanded
A23: Jan | B23: =SUM('Monthly Demand'!C2:C31) -> 11590
A24: Feb | B24: =SUM('Monthly Demand'!D2:D31) -> 11174
A25: Mar | B25: =SUM('Monthly Demand'!E2:E31) -> 10582
A26: Apr | B26: =SUM('Monthly Demand'!F2:F31) -> 10198
A27: May | B27: =SUM('Monthly Demand'!G2:G31) -> 10250
A28: Jun | B28: =SUM('Monthly Demand'!H2:H31) -> 9884
A29: Jul | B29: =SUM('Monthly Demand'!I2:I31) -> 10000
A30: Aug | B30: =SUM('Monthly Demand'!J2:J31) -> 10356
A31: Sep | B31: =SUM('Monthly Demand'!K2:K31) -> 10674
A32: Oct | B32: =SUM('Monthly Demand'!L2:L31) -> 10830
A33: Nov | B33: =SUM('Monthly Demand'!M2:M31) -> 11525
A34: Dec | B34: =SUM('Monthly Demand'!N2:N31) -> 11827
A37: Helper tables above feed the charts below. Edit source data in Product Master / Monthly Demand / Expiry Tracker — every KPI and chart recalculates automatically.
A40: Top 10 SKUs by Inventory Value
A41: Product Name | B41: Inventory Value ($)
A42: =INDEX('Inventory Analysis'!$B$5:$B$34,MATCH(1,'Inventory Analysis'!$R$5:$R$34,0)) -> Acyclovir 400mg Tablets | B42: =INDEX('Inventory Analysis'!$Q$5:$Q$34,MATCH(1,'Inventory Analysis'!$R$5:$R$34,0)) -> 7377.244
A43: =INDEX('Inventory Analysis'!$B$5:$B$34,MATCH(2,'Inventory Analysis'!$R$5:$R$34,0)) -> Insulin Glargine Injection | B43: =INDEX('Inventory Analysis'!$Q$5:$Q$34,MATCH(2,'Inventory Analysis'!$R$5:$R$34,0)) -> 6569.64
A44: =INDEX('Inventory Analysis'!$B$5:$B$34,MATCH(3,'Inventory Analysis'!$R$5:$R$34,0)) -> Tetanus Toxoid Vaccine (Dose) | B44: =INDEX('Inventory Analysis'!$Q$5:$Q$34,MATCH(3,'Inventory Analysis'!$R$5:$R$34,0)) -> 3874.44
A45: =INDEX('Inventory Analysis'!$B$5:$B$34,MATCH(4,'Inventory Analysis'!$R$5:$R$34,0)) -> Influenza Vaccine (Dose) | B45: =INDEX('Inventory Analysis'!$Q$5:$Q$34,MATCH(4,'Inventory Analysis'!$R$5:$R$34,0)) -> 2304.45
A46: =INDEX('Inventory Analysis'!$B$5:$B$34,MATCH(5,'Inventory Analysis'!$R$5:$R$34,0)) -> Montelukast 10mg Tablets | B46: =INDEX('Inventory Analysis'!$Q$5:$Q$34,MATCH(5,'Inventory Analysis'!$R$5:$R$34,0)) -> 2211.545
A47: =INDEX('Inventory Analysis'!$B$5:$B$34,MATCH(6,'Inventory Analysis'!$R$5:$R$34,0)) -> Doxycycline 100mg Capsules | B47: =INDEX('Inventory Analysis'!$Q$5:$Q$34,MATCH(6,'Inventory Analysis'!$R$5:$R$34,0)) -> 2069.464
A48: =INDEX('Inventory Analysis'!$B$5:$B$34,MATCH(7,'Inventory Analysis'!$R$5:$R$34,0)) -> Azithromycin 250mg Tablets | B48: =INDEX('Inventory Analysis'!$Q$5:$Q$34,MATCH(7,'Inventory Analysis'!$R$5:$R$34,0)) -> 1737.285
A49: =INDEX('Inventory Analysis'!$B$5:$B$34,MATCH(8,'Inventory Analysis'!$R$5:$R$34,0)) -> Ciprofloxacin 500mg Tablets | B49: =INDEX('Inventory Analysis'!$Q$5:$Q$34,MATCH(8,'Inventory Analysis'!$R$5:$R$34,0)) -> 1552.284
...

Sheet Product Master
A1: SKU ID | B1: Product Name | C1: Category | D1: Supplier | E1: Storage Condition | F1: Unit Cost ($) | G1: Selling Price ($) | H1: Current Stock (Units) | I1: Lead Time (Days) | J1: Ordering Cost/Order ($) | K1: Annual Holding Cost (%) | L1: Min Order Qty (Units)
A2: PH-001 | B2: Paracetamol 500mg Tablets | C2: Analgesics | D2: MedSource Distributors | E2: Room Temp (15-25°C) | F2: 0.071 | G2: 0.097 | H2: 6003 | I2: 10 | J2: 121.01 | K2: 0.197 | L2: 1000
A3: PH-002 | B3: Ibuprofen 400mg Tablets | C3: Analgesics | D3: Generic Pharma Supplies Ltd | E3: Room Temp (15-25°C) | F3: 0.021 | G3: 0.037 | H3: 12133 | I3: 14 | J3: 57.1 | K3: 0.217 | L3: 250
A4: PH-003 | B4: Aspirin 75mg Tablets | C4: Analgesics | D4: Global Health Logistics | E4: Room Temp (15-25°C) | F4: 0.091 | G4: 0.139 | H4: 98 | I4: 7 | J4: 112.74 | K4: 0.204 | L4: 100
A5: PH-004 | B5: Diclofenac Gel 1% | C5: Analgesics | D5: BioMed Partners Inc. | E5: Room Temp (15-25°C) | F5: 0.063 | G5: 0.093 | H5: 9033 | I5: 30 | J5: 115.7 | K5: 0.165 | L5: 250
A6: PH-005 | B6: Amoxicillin 500mg Capsules | C6: Antibiotics | D6: CarePlus Pharmaceuticals | E6: Room Temp (15-25°C) | F6: 0.324 | G6: 0.512 | H6: 2273 | I6: 30 | J6: 101.75 | K6: 0.168 | L6: 1000
A7: PH-006 | B7: Azithromycin 250mg Tablets | C7: Antibiotics | D7: PharmaLink Trading Co. | E7: Room Temp (15-25°C) | F7: 0.165 | G7: 0.272 | H7: 10529 | I7: 21 | J7: 134.69 | K7: 0.151 | L7: 100
A8: PH-007 | B8: Ciprofloxacin 500mg Tablets | C8: Antibiotics | D8: MedSource Distributors | E8: Room Temp (15-25°C) | F8: 0.324 | G8: 0.578 | H8: 4791 | I8: 21 | J8: 106.99 | K8: 0.161 | L8: 200
A9: PH-008 | B9: Doxycycline 100mg Capsules | C9: Antibiotics | D9: Generic Pharma Supplies Ltd | E9: Room Temp (15-25°C) | F9: 0.334 | G9: 0.465 | H9: 6196 | I9: 21 | J9: 124.24 | K9: 0.159 | L9: 500
A10: PH-009 | B10: Metronidazole 400mg Tablets | C10: Antibiotics | D10: Global Health Logistics | E10: Room Temp (15-25°C) | F10: 0.32 | G10: 0.504 | H10: 66 | I10: 14 | J10: 42.31 | K10: 0.189 | L10: 1000
A11: PH-010 | B11: Metformin 500mg Tablets | C11: Antidiabetics | D11: BioMed Partners Inc. | E11: Room Temp (15-25°C) | F11: 0.099 | G11: 0.157 | H11: 13270 | I11: 10 | J11: 50.38 | K11: 0.196 | L11: 250
A12: PH-011 | B12: Insulin Glargine Injection | C12: Antidiabetics | D12: CarePlus Pharmaceuticals | E12: Cold Chain (2-8°C) | F12: 17.38 | G12: 25.884 | H12: 378 | I12: 30 | J12: 268.63 | K12: 0.309 | L12: 1000
A13: PH-012 | B13: Glimepiride 2mg Tablets | C13: Antidiabetics | D13: PharmaLink Trading Co. | E13: Room Temp (15-25°C) | F13: 0.03 | G13: 0.046 | H13: 8068 | I13: 30 | J13: 145.3 | K13: 0.22 | L13: 1000
... A31: PH-030 | B31: Hydrocortisone Cream 1% | C31: Dermatological | D31: PharmaLink Trading Co. | E31: Room Temp (15-25°C) | F31: 1.521 | G31: 2.379 | H31: 608 | I31: 30 | J31: 77.54 | K31: 0.209 | L31: 500
A33: Note: Sample data generated for this project template. Replace with actual ERP/WMS export (SKU master, cost, supplier lead times) when adapting to a real pharmacy or distributor.

Sheet Monthly Demand
A1: SKU ID | B1: Product Name | C1: Jan | D1: Feb | E1: Mar | F1: Apr | G1: May | H1: Jun | I1: Jul | J1: Aug | K1: Sep | L1: Oct | M1: Nov | N1: Dec | O1: Total Annual Demand | P1: Avg Monthly Demand | Q1: Std Dev Monthly Demand
A2: PH-001 | B2: Paracetamol 500mg Tablets | C2: 394 | D2: 430 | E2: 388 | F2: 408 | G2: 438 | H2: 388 | I2: 406 | J2: 453 | K2: 442 | L2: 408 | M2: 447 | N2: 470 | O2: =SUM(C2:N2) -> 5072 | P2: =AVERAGE(C2:N2) -> 422.66667 | Q2: =STDEV(C2:N2) -> 27.549405
A3: PH-002 | B3: Ibuprofen 400mg Tablets | C3: 657 | D3: 706 | E3: 702 | F3: 699 | G3: 686 | H3: 647 | I3: 720 | J3: 661 | K3: 800 | L3: 653 | M3: 691 | N3: 749 | O3: =SUM(C3:N3) -> 8371 | P3: =AVERAGE(C3:N3) -> 697.58333 | Q3: =STDEV(C3:N3) -> 44.145335
A4: PH-003 | B4: Aspirin 75mg Tablets | C4: 414 | D4: 415 | E4: 370 | F4: 377 | G4: 412 | H4: 350 | I4: 368 | J4: 397 | K4: 400 | L4: 398 | M4: 342 | N4: 394 | O4: =SUM(C4:N4) -> 4637 | P4: =AVERAGE(C4:N4) -> 386.41667 | Q4: =STDEV(C4:N4) -> 24.710904
A5: PH-004 | B5: Diclofenac Gel 1% | C5: 612 | D5: 603 | E5: 529 | F5: 502 | G5: 540 | H5: 534 | I5: 526 | J5: 626 | K5: 617 | L5: 540 | M5: 587 | N5: 551 | O5: =SUM(C5:N5) -> 6767 | P5: =AVERAGE(C5:N5) -> 563.91667 | Q5: =STDEV(C5:N5) -> 42.363059
A6: PH-005 | B6: Amoxicillin 500mg Capsules | C6: 243 | D6: 233 | E6: 193 | F6: 202 | G6: 148 | H6: 152 | I6: 162 | J6: 176 | K6: 166 | L6: 192 | M6: 248 | N6: 253 | O6: =SUM(C6:N6) -> 2368 | P6: =AVERAGE(C6:N6) -> 197.33333 | Q6: =STDEV(C6:N6) -> 38.455011
A7: PH-006 | B7: Azithromycin 250mg Tablets | C7: 773 | D7: 689 | E7: 565 | F7: 559 | G7: 439 | H7: 448 | I7: 451 | J7: 537 | K7: 590 | L7: 591 | M7: 712 | N7: 683 | O7: =SUM(C7:N7) -> 7037 | P7: =AVERAGE(C7:N7) -> 586.41667 | Q7: =STDEV(C7:N7) -> 110.10364
A8: PH-007 | B8: Ciprofloxacin 500mg Tablets | C8: 265 | D8: 258 | E8: 213 | F8: 169 | G8: 164 | H8: 143 | I8: 178 | J8: 187 | K8: 207 | L8: 212 | M8: 226 | N8: 286 | O8: =SUM(C8:N8) -> 2508 | P8: =AVERAGE(C8:N8) -> 209 | Q8: =STDEV(C8:N8) -> 43.911067
A9: PH-008 | B9: Doxycycline 100mg Capsules | C9: 383 | D9: 293 | E9: 281 | F9: 259 | G9: 251 | H9: 235 | I9: 226 | J9: 236 | K9: 265 | L9: 285 | M9: 346 | N9: 335 | O9: =SUM(C9:N9) -> 3395 | P9: =AVERAGE(C9:N9) -> 282.91667 | Q9: =STDEV(C9:N9) -> 49.051843
A10: PH-009 | B10: Metronidazole 400mg Tablets | C10: 224 | D10: 199 | E10: 200 | F10: 164 | G10: 172 | H10: 160 | I10: 132 | J10: 147 | K10: 182 | L10: 189 | M10: 210 | N10: 265 | O10: =SUM(C10:N10) -> 2244 | P10: =AVERAGE(C10:N10) -> 187 | Q10: =STDEV(C10:N10) -> 36.221541
A11: PH-010 | B11: Metformin 500mg Tablets | C11: 562 | D11: 568 | E11: 604 | F11: 597 | G11: 639 | H11: 518 | I11: 559 | J11: 551 | K11: 623 | L11: 538 | M11: 530 | N11: 566 | O11: =SUM(C11:N11) -> 6855 | P11: =AVERAGE(C11:N11) -> 571.25 | Q11: =STDEV(C11:N11) -> 37.331744
A12: PH-011 | B12: Insulin Glargine Injection | C12: 14 | D12: 16 | E12: 16 | F12: 14 | G12: 14 | H12: 17 | I12: 15 | J12: 15 | K12: 16 | L12: 17 | M12: 17 | N12: 14 | O12: =SUM(C12:N12) -> 185 | P12: =AVERAGE(C12:N12) -> 15.416667 | Q12: =STDEV(C12:N12) -> 1.2401124
A13: PH-012 | B13: Glimepiride 2mg Tablets | C13: 582 | D13: 559 | E13: 519 | F13: 523 | G13: 501 | H13: 592 | I13: 502 | J13: 536 | K13: 500 | L13: 557 | M13: 617 | N13: 565 | O13: =SUM(C13:N13) -> 6553 | P13: =AVERAGE(C13:N13) -> 546.08333 | Q13: =STDEV(C13:N13) -> 38.77548
... A31: PH-030 | B31: Hydrocortisone Cream 1% | C31: 51 | D31: 63 | E31: 58 | F31: 61 | G31: 59 | H31: 56 | I31: 60 | J31: 63 | K31: 53 | L31: 61 | M31: 57 | N31: 56 | O31: =SUM(C31:N31) -> 698 | P31: =AVERAGE(C31:N31) -> 58.166667 | Q31: =STDEV(C31:N31) -> 3.76185

Sheet Inventory Analysis
A1: Inventory Analysis — EOQ, Safety Stock, Reorder Point & ABC Classification
A2: Service Level Z-Score: | B2: 1.65 | C2: (1.28 = 90% service level, 1.65 = 95%, 2.33 = 99%)
A4: SKU ID | B4: Product Name | C4: Category | D4: Current Stock | E4: Unit Cost ($) | F4: Annual Demand | G4: Avg Monthly Demand | H4: StdDev Monthly Demand | I4: Lead Time (Days) | J4: Ordering Cost ($) | K4: Holding Cost (%) | L4: Holding Cost/Unit ($) | M4: EOQ (Units) | N4: Avg Daily Demand | O4: Safety Stock (Units) | P4: Reorder Point (Units) | Q4: Annual Inventory Value ($) | R4: Value Rank | S4: Cumulative Value ($) | T4: Cumulative % | U4: ABC Class | V4: Stock Status | W4: Suggested Order Qty (Units)
A5: ='Product Master'!A2 -> PH-001 | B5: ='Product Master'!B2 -> Paracetamol 500mg Tablets | C5: ='Product Master'!C2 -> Analgesics | D5: =INDEX('Product Master'!$H$2:$H$31,MATCH($A5,'Product Master'!$A$2:$A$31,0)) -> 6003 | E5: =INDEX('Product Master'!$F$2:$F$31,MATCH($A5,'Product Master'!$A$2:$A$31,0)) -> 0.071 | F5: =INDEX('Monthly Demand'!$O$2:$O$31,MATCH($A5,'Monthly Demand'!$A$2:$A$31,0)) -> 5072 | G5: =INDEX('Monthly Demand'!$P$2:$P$31,MATCH($A5,'Monthly Demand'!$A$2:$A$31,0)) -> 422.66667 | H5: =INDEX('Monthly Demand'!$Q$2:$Q$31,MATCH($A5,'Monthly Demand'!$A$2:$A$31,0)) -> 27.549405 | I5: =INDEX('Product Master'!$I$2:$I$31,MATCH($A5,'Product Master'!$A$2:$A$31,0)) -> 10 | J5: =INDEX('Product Master'!$J$2:$J$31,MATCH($A5,'Product Master'!$A$2:$A$31,0)) -> 121.01 | K5: =INDEX('Product Master'!$K$2:$K$31,MATCH($A5,'Product Master'!$A$2:$A$31,0)) -> 0.197 | L5: =E5*K5 -> 0.013987 | M5: =IFERROR(SQRT(2*F5*J5/L5),0) -> 9368.1312 | N5: =F5/365 -> 13.89589 | O5: =$B$2*H5*SQRT(I5/30) -> 26.244333 | P5: =N5*I5+O5 -> 165.20324 | Q5: =D5*E5 -> 426.213 | R5: =RANK(Q5,$Q$5:$Q$34) -> 17 | S5: =SUMPRODUCT(($R$5:$R$34<=R5)*$Q$5:$Q$34) -> 34840.566 | T5: =S5/SUM($Q$5:$Q$34) -> 0.93270064 | U5: =IF(T5<=0.7,"A",IF(T5<=0.9,"B","C")) -> C | V5: =IF(D5<P5,"Reorder Now",IF(D5>M5*2,"Overstock","OK")) -> OK | W5: =IF(V5="Reorder Now",ROUND(MAX(M5,INDEX('Product Master'!$L$2:$L$31,MATCH($A5,'Product Master'!$A$2:$A$31,0))),0),0) -> 0
A6: ='Product Master'!A3 -> PH-002 | B6: ='Product Master'!B3 -> Ibuprofen 400mg Tablets | C6: ='Product Master'!C3 -> Analgesics | D6: =INDEX('Product Master'!$H$2:$H$31,MATCH($A6,'Product Master'!$A$2:$A$31,0)) -> 12133 | E6: =INDEX('Product Master'!$F$2:$F$31,MATCH($A6,'Product Master'!$A$2:$A$31,0)) -> 0.021 | F6: =INDEX('Monthly Demand'!$O$2:$O$31,MATCH($A6,'Monthly Demand'!$A$2:$A$31,0)) -> 8371 | G6: =INDEX('Monthly Demand'!$P$2:$P$31,MATCH($A6,'Monthly Demand'!$A$2:$A$31,0)) -> 697.58333 | H6: =INDEX('Monthly Demand'!$Q$2:$Q$31,MATCH($A6,'Monthly Demand'!$A$2:$A$31,0)) -> 44.145335 | I6: =INDEX('Product Master'!$I$2:$I$31,MATCH($A6,'Product Master'!$A$2:$A$31,0)) -> 14 | J6: =INDEX('Product Master'!$J$2:$J$31,MATCH($A6,'Product Master'!$A$2:$A$31,0)) -> 57.1 | K6: =INDEX('Product Master'!$K$2:$K$31,MATCH($A6,'Product Master'!$A$2:$A$31,0)) -> 0.217 | L6: =E6*K6 -> 0.004557 | M6: =IFERROR(SQRT(2*F6*J6/L6),0) -> 14483.79 | N6: =F6/365 -> 22.934247 | O6: =$B$2*H6*SQRT(I6/30) -> 49.759058 | P6: =N6*I6+O6 -> 370.83851 | Q6: =D6*E6 -> 254.793 | R6: =RANK(Q6,$Q$5:$Q$34) -> 21 | S6: =SUMPRODUCT(($R$5:$R$34<=R6)*$Q$5:$Q$34) -> 36275.448 | T6: =S6/SUM($Q$5:$Q$34) -> 0.9711132 | U6: =IF(T6<=0.7,"A",IF(T6<=0.9,"B","C")) -> C | V6: =IF(D6<P6,"Reorder Now",IF(D6>M6*2,"Overstock","OK")) -> OK | W6: =IF(V6="Reorder Now",ROUND(MAX(M6,INDEX('Product Master'!$L$2:$L$31,MATCH($A6,'Product Master'!$A$2:$A$31,0))),0),0) -> 0
A7: ='Product Master'!A4 -> PH-003 | B7: ='Product Master'!B4 -> Aspirin 75mg Tablets | C7: ='Product Master'!C4 -> Analgesics | D7: =INDEX('Product Master'!$H$2:$H$31,MATCH($A7,'Product Master'!$A$2:$A$31,0)) -> 98 | E7: =INDEX('Product Master'!$F$2:$F$31,MATCH($A7,'Product Master'!$A$2:$A$31,0)) -> 0.091 | F7: =INDEX('Monthly Demand'!$O$2:$O$31,MATCH($A7,'Monthly Demand'!$A$2:$A$31,0)) -> 4637 | G7: =INDEX('Monthly Demand'!$P$2:$P$31,MATCH($A7,'Monthly Demand'!$A$2:$A$31,0)) -> 386.41667 | H7: =INDEX('Monthly Demand'!$Q$2:$Q$31,MATCH($A7,'Monthly Demand'!$A$2:$A$31,0)) -> 24.710904 | I7: =INDEX('Product Master'!$I$2:$I$31,MATCH($A7,'Product Master'!$A$2:$A$31,0)) -> 7 | J7: =INDEX('Product Master'!$J$2:$J$31,MATCH($A7,'Product Master'!$A$2:$A$31,0)) -> 112.74 | K7: =INDEX('Product Master'!$K$2:$K$31,MATCH($A7,'Product Master'!$A$2:$A$31,0)) -> 0.204 | L7: =E7*K7 -> 0.018564 | M7: =IFERROR(SQRT(2*F7*J7/L7),0) -> 7504.7595 | N7: =F7/365 -> 12.70411 | O7: =$B$2*H7*SQRT(I7/30) -> 19.695226 | P7: =N7*I7+O7 -> 108.62399 | Q7: =D7*E7 -> 8.918 | R7: =RANK(Q7,$Q$5:$Q$34) -> 29 | S7: =SUMPRODUCT(($R$5:$R$34<=R7)*$Q$5:$Q$34) -> 37345.924 | T7: =S7/SUM($Q$5:$Q$34) -> 0.99977042 | U7: =IF(T7<=0.7,"A",IF(T7<=0.9,"B","C")) -> C | V7: =IF(D7<P7,"Reorder Now",IF(D7>M7*2,"Overstock","OK")) -> Reorder Now | W7: =IF(V7="Reorder Now",ROUND(MAX(M7,INDEX('Product Master'!$L$2:$L$31,MATCH($A7,'Product Master'!$A$2:$A$31,0))),0),0) -> 7505
A8: ='Product Master'!A5 -> PH-004 | B8: ='Product Master'!B5 -> Diclofenac Gel 1% | C8: ='Product Master'!C5 -> Analgesics | D8: =INDEX('Product Master'!$H$2:$H$31,MATCH($A8,'Product Master'!$A$2:$A$31,0)) -> 9033 | E8: =INDEX('Product Master'!$F$2:$F$31,MATCH($A8,'Product Master'!$A$2:$A$31,0)) -> 0.063 | F8: =INDEX('Monthly Demand'!$O$2:$O$31,MATCH($A8,'Monthly Demand'!$A$2:$A$31,0)) -> 6767 | G8: =INDEX('Monthly Demand'!$P$2:$P$31,MATCH($A8,'Monthly Demand'!$A$2:$A$31,0)) -> 563.91667 | H8: =INDEX('Monthly Demand'!$Q$2:$Q$31,MATCH($A8,'Monthly Demand'!$A$2:$A$31,0)) -> 42.363059 | I8: =INDEX('Product Master'!$I$2:$I$31,MATCH($A8,'Product Master'!$A$2:$A$31,0)) -> 30 | J8: =INDEX('Product Master'!$J$2:$J$31,MATCH($A8,'Product Master'!$A$2:$A$31,0)) -> 115.7 | K8: =INDEX('Product Master'!$K$2:$K$31,MATCH($A8,'Product Master'!$A$2:$A$31,0)) -> 0.165 | L8: =E8*K8 -> 0.010395 | M8: =IFERROR(SQRT(2*F8*J8/L8),0) -> 12273.474 | N8: =F8/365 -> 18.539726 | O8: =$B$2*H8*SQRT(I8/30) -> 69.899048 | P8: =N8*I8+O8 -> 626.09083 | Q8: =D8*E8 -> 569.079 | R8: =RANK(Q8,$Q$5:$Q$34) -> 16 | S8: =SUMPRODUCT(($R$5:$R$34<=R8)*$Q$5:$Q$34) -> 34414.353 | T8: =S8/SUM($Q$5:$Q$34) -> 0.92129069 | U8: =IF(T8<=0.7,"A",IF(T8<=0.9,"B","C")) -> C | V8: =IF(D8<P8,"Reorder Now",IF(D8>M8*2,"Overstock","OK")) -> OK | W8: =IF(V8="Reorder Now",ROUND(MAX(M8,INDEX('Product Master'!$L$2:$L$31,MATCH($A8,'Product Master'!$A$2:$A$31,0))),0),0) -> 0
A9: ='Product Master'!A6 -> PH-005 | B9: ='Product Master'!B6 -> Amoxicillin 500mg Capsules | C9: ='Product Master'!C6 -> Antibiotics | D9: =INDEX('Product Master'!$H$2:$H$31,MATCH($A9,'Product Master'!$A$2:$A$31,0)) -> 2273 | E9: =INDEX('Product Master'!$F$2:$F$31,MATCH($A9,'Product Master'!$A$2:$A$31,0)) -> 0.324 | F9: =INDEX('Monthly Demand'!$O$2:$O$31,MATCH($A9,'Monthly Demand'!$A$2:$A$31,0)) -> 2368 | G9: =INDEX('Monthly Demand'!$P$2:$P$31,MATCH($A9,'Monthly Demand'!$A$2:$A$31,0)) -> 197.33333 | H9: =INDEX('Monthly Demand'!$Q$2:$Q$31,MATCH($A9,'Monthly Demand'!$A$2:$A$31,0)) -> 38.455011 | I9: =INDEX('Product Master'!$I$2:$I$31,MATCH($A9,'Product Master'!$A$2:$A$31,0)) -> 30 | J9: =INDEX('Product Master'!$J$2:$J$31,MATCH($A9,'Product Master'!$A$2:$A$31,0)) -> 101.75 | K9: =INDEX('Product Master'!$K$2:$K$31,MATCH($A9,'Product Master'!$A$2:$A$31,0)) -> 0.168 | L9: =E9*K9 -> 0.054432 | M9: =IFERROR(SQRT(2*F9*J9/L9),0) -> 2975.4038 | N9: =F9/365 -> 6.4876712 | O9: =$B$2*H9*SQRT(I9/30) -> 63.450768 | P9: =N9*I9+O9 -> 258.08091 | Q9: =D9*E9 -> 736.452 | R9: =RANK(Q9,$Q$5:$Q$34) -> 14 | S9: =SUMPRODUCT(($R$5:$R$34<=R9)*$Q$5:$Q$34) -> 33149.634 | T9: =S9/SUM($Q$5:$Q$34) -> 0.88743348 | U9: =IF(T9<=0.7,"A",IF(T9<=0.9,"B","C")) -> B | V9: =IF(D9<P9,"Reorder Now",IF(D9>M9*2,"Overstock","OK")) -> OK | W9: =IF(V9="Reorder Now",ROUND(MAX(M9,INDEX('Product Master'!$L$2:$L$31,MATCH($A9,'Product Master'!$A$2:$A$31,0))),0),0) -> 0
A10: ='Product Master'!A7 -> PH-006 | B10: ='Product Master'!B7 -> Azithromycin 250mg Tablets | C10: ='Product Master'!C7 -> Antibiotics | D10: =INDEX('Product Master'!$H$2:$H$31,MATCH($A10,'Product Master'!$A$2:$A$31,0)) -> 10529 | E10: =INDEX('Product Master'!$F$2:$F$31,MATCH($A10,'Product Master'!$A$2:$A$31,0)) -> 0.165 | F10: =INDEX('Monthly Demand'!$O$2:$O$31,MATCH($A10,'Monthly Demand'!$A$2:$A$31,0)) -> 7037 | G10: =INDEX('Monthly Demand'!$P$2:$P$31,MATCH($A10,'Monthly Demand'!$A$2:$A$31,0)) -> 586.41667 | H10: =INDEX('Monthly Demand'!$Q$2:$Q$31,MATCH($A10,'Monthly Demand'!$A$2:$A$31,0)) -> 110.10364 | I10: =INDEX('Product Master'!$I$2:$I$31,MATCH($A10,'Product Master'!$A$2:$A$31,0)) -> 21 | J10: =INDEX('Product Master'!$J$2:$J$31,MATCH($A10,'Product Master'!$A$2:$A$31,0)) -> 134.69 | K10: =INDEX('Product Master'!$K$2:$K$31,MATCH($A10,'Product Master'!$A$2:$A$31,0)) -> 0.151 | L10: =E10*K10 -> 0.024915 | M10: =IFERROR(SQRT(2*F10*J10/L10),0) -> 8722.6009 | N10: =F10/365 -> 19.279452 | O10: =$B$2*H10*SQRT(I10/30) -> 151.99686 | P10: =N10*I10+O10 -> 556.86536 | Q10: =D10*E10 -> 1737.285 | R10: =RANK(Q10,$Q$5:$Q$34) -> 7 | S10: =SUMPRODUCT(($R$5:$R$34<=R10)*$Q$5:$Q$34) -> 26144.068 | T10: =S10/SUM($Q$5:$Q$34) -> 0.69989072 | U10: =IF(T10<=0.7,"A",IF(T10<=0.9,"B","C")) -> A | V10: =IF(D10<P10,"Reorder Now",IF(D10>M10*2,"Overstock","OK")) -> OK | W10: =IF(V10="Reorder Now",ROUND(MAX(M10,INDEX('Product Master'!$L$2:$L$31,MATCH($A10,'Product Master'!$A$2:$A$31,0))),0),0) -> 0
A11: ='Product Master'!A8 -> PH-007 | B11: ='Product Master'!B8 -> Ciprofloxacin 500mg Tablets | C11: ='Product Master'!C8 -> Antibiotics | D11: =INDEX('Product Master'!$H$2:$H$31,MATCH($A11,'Product Master'!$A$2:$A$31,0)) -> 4791 | E11: =INDEX('Product Master'!$F$2:$F$31,MATCH($A11,'Product Master'!$A$2:$A$31,0)) -> 0.324 | F11: =INDEX('Monthly Demand'!$O$2:$O$31,MATCH($A11,'Monthly Demand'!$A$2:$A$31,0)) -> 2508 | G11: =INDEX('Monthly Demand'!$P$2:$P$31,MATCH($A11,'Monthly Demand'!$A$2:$A$31,0)) -> 209 | H11: =INDEX('Monthly Demand'!$Q$2:$Q$31,MATCH($A11,'Monthly Demand'!$A$2:$A$31,0)) -> 43.911067 | I11: =INDEX('Product Master'!$I$2:$I$31,MATCH($A11,'Product Master'!$A$2:$A$31,0)) -> 21 | J11: =INDEX('Product Master'!$J$2:$J$31,MATCH($A11,'Product Master'!$A$2:$A$31,0)) -> 106.99 | K11: =INDEX('Product Master'!$K$2:$K$31,MATCH($A11,'Product Master'!$A$2:$A$31,0)) -> 0.161 | L11: =E11*K11 -> 0.052164 | M11: =IFERROR(SQRT(2*F11*J11/L11),0) -> 3207.4871 | N11: =F11/365 -> 6.8712329 | O11: =$B$2*H11*SQRT(I11/30) -> 60.618747 | P11: =N11*I11+O11 -> 204.91464 | Q11: =D11*E11 -> 1552.284 | R11: =RANK(Q11,$Q$5:$Q$34) -> 8 | S11: =SUMPRODUCT(($R$5:$R$34<=R11)*$Q$5:$Q$34) -> 27696.352 | T11: =S11/SUM($Q$5:$Q$34) -> 0.7414462 | U11: =IF(T11<=0.7,"A",IF(T11<=0.9,"B","C")) -> B | V11: =IF(D11<P11,"Reorder Now",IF(D11>M11*2,"Overstock","OK")) -> OK | W11: =IF(V11="Reorder Now",ROUND(MAX(M11,INDEX('Product Master'!$L$2:$L$31,MATCH($A11,'Product Master'!$A$2:$A$31,0))),0),0) -> 0
A12: ='Product Master'!A9 -> PH-008 | B12: ='Product Master'!B9 -> Doxycycline 100mg Capsules | C12: ='Product Master'!C9 -> Antibiotics | D12: =INDEX('Product Master'!$H$2:$H$31,MATCH($A12,'Product Master'!$A$2:$A$31,0)) -> 6196 | E12: =INDEX('Product Master'!$F$2:$F$31,MATCH($A12,'Product Master'!$A$2:$A$31,0)) -> 0.334 | F12: =INDEX('Monthly Demand'!$O$2:$O$31,MATCH($A12,'Monthly Demand'!$A$2:$A$31,0)) -> 3395 | G12: =INDEX('Monthly Demand'!$P$2:$P$31,MATCH($A12,'Monthly Demand'!$A$2:$A$31,0)) -> 282.91667 | H12: =INDEX('Monthly Demand'!$Q$2:$Q$31,MATCH($A12,'Monthly Demand'!$A$2:$A$31,0)) -> 49.051843 | I12: =INDEX('Product Master'!$I$2:$I$31,MATCH($A12,'Product Master'!$A$2:$A$31,0)) -> 21 | J12: =INDEX('Product Master'!$J$2:$J$31,MATCH($A12,'Product Master'!$A$2:$A$31,0)) -> 124.24 | K12: =INDEX('Product Master'!$K$2:$K$31,MATCH($A12,'Product Master'!$A$2:$A$31,0)) -> 0.159 | L12: =E12*K12 -> 0.053106 | M12: =IFERROR(SQRT(2*F12*J12/L12),0) -> 3985.6009 | N12: =F12/365 -> 9.3013699 | O12: =$B$2*H12*SQRT(I12/30) -> 67.715532 | P12: =N12*I12+O12 -> 263.0443 | Q12: =D12*E12 -> 2069.464 | R12: =RANK(Q12,$Q$5:$Q$34) -> 6 | S12: =SUMPRODUCT(($R$5:$R$34<=R12)*$Q$5:$Q$34) -> 24406.783 | T12: =S12/SUM($Q$5:$Q$34) -> 0.65338267 | U12: =IF(T12<=0.7,"A",IF(T12<=0.9,"B","C")) -> A | V12: =IF(D12<P12,"Reorder Now",IF(D12>M12*2,"Overstock","OK")) -> OK | W12: =IF(V12="Reorder Now",ROUND(MAX(M12,INDEX('Product Master'!$L$2:$L$31,MATCH($A12,'Product Master'!$A$2:$A$31,0))),0),0) -> 0
A13: ='Product Master'!A10 -> PH-009 | B13: ='Product Master'!B10 -> Metronidazole 400mg Tablets | C13: ='Product Master'!C10 -> Antibiotics | D13: =INDEX('Product Master'!$H$2:$H$31,MATCH($A13,'Product Master'!$A$2:$A$31,0)) -> 66 | E13: =INDEX('Product Master'!$F$2:$F$31,MATCH($A13,'Product Master'!$A$2:$A$31,0)) -> 0.32 | F13: =INDEX('Monthly Demand'!$O$2:$O$31,MATCH($A13,'Monthly Demand'!$A$2:$A$31,0)) -> 2244 | G13: =INDEX('Monthly Demand'!$P$2:$P$31,MATCH($A13,'Monthly Demand'!$A$2:$A$31,0)) -> 187 | H13: =INDEX('Monthly Demand'!$Q$2:$Q$31,MATCH($A13,'Monthly Demand'!$A$2:$A$31,0)) -> 36.221541 | I13: =INDEX('Product Master'!$I$2:$I$31,MATCH($A13,'Product Master'!$A$2:$A$31,0)) -> 14 | J13: =INDEX('Product Master'!$J$2:$J$31,MATCH($A13,'Product Master'!$A$2:$A$31,0)) -> 42.31 | K13: =INDEX('Product Master'!$K$2:$K$31,MATCH($A13,'Product Master'!$A$2:$A$31,0)) -> 0.189 | L13: =E13*K13 -> 0.06048 | M13: =IFERROR(SQRT(2*F13*J13/L13),0) -> 1771.9116 | N13: =F13/365 -> 6.1479452 | O13: =$B$2*H13*SQRT(I13/30) -> 40.827638 | P13: =N13*I13+O13 -> 126.89887 | Q13: =D13*E13 -> 21.12 | R13: =RANK(Q13,$Q$5:$Q$34) -> 28 | S13: =SUMPRODUCT(($R$5:$R$34<=R13)*$Q$5:$Q$34) -> 37337.006 | T13: =S13/SUM($Q$5:$Q$34) -> 0.99953168 | U13: =IF(T13<=0.7,"A",IF(T13<=0.9,"B","C")) -> C | V13: =IF(D13<P13,"Reorder Now",IF(D13>M13*2,"Overstock","OK")) -> Reorder Now | W13: =IF(V13="Reorder Now",ROUND(MAX(M13,INDEX('Product Master'!$L$2:$L$31,MATCH($A13,'Product Master'!$A$2:$A$31,0))),0),0) -> 1772
A14: ='Product Master'!A11 -> PH-010 | B14: ='Product Master'!B11 -> Metformin 500mg Tablets | C14: ='Product Master'!C11 -> Antidiabetics | D14: =INDEX('Product Master'!$H$2:$H$31,MATCH($A14,'Product Master'!$A$2:$A$31,0)) -> 13270 | E14: =INDEX('Product Master'!$F$2:$F$31,MATCH($A14,'Product Master'!$A$2:$A$31,0)) -> 0.099 | F14: =INDEX('Monthly Demand'!$O$2:$O$31,MATCH($A14,'Monthly Demand'!$A$2:$A$31,0)) -> 6855 | G14: =INDEX('Monthly Demand'!$P$2:$P$31,MATCH($A14,'Monthly Demand'!$A$2:$A$31,0)) -> 571.25 | H14: =INDEX('Monthly Demand'!$Q$2:$Q$31,MATCH($A14,'Monthly Demand'!$A$2:$A$31,0)) -> 37.331744 | I14: =INDEX('Product Master'!$I$2:$I$31,MATCH($A14,'Product Master'!$A$2:$A$31,0)) -> 10 | J14: =INDEX('Product Master'!$J$2:$J$31,MATCH($A14,'Product Master'!$A$2:$A$31,0)) -> 50.38 | K14: =INDEX('Product Master'!$K$2:$K$31,MATCH($A14,'Product Master'!$A$2:$A$31,0)) -> 0.196 | L14: =E14*K14 -> 0.019404 | M14: =IFERROR(SQRT(2*F14*J14/L14),0) -> 5966.26 | N14: =F14/365 -> 18.780822 | O14: =$B$2*H14*SQRT(I14/30) -> 35.563262 | P14: =N14*I14+O14 -> 223.37148 | Q14: =D14*E14 -> 1313.73 | R14: =RANK(Q14,$Q$5:$Q$34) -> 9 | S14: =SUMPRODUCT(($R$5:$R$34<=R14)*$Q$5:$Q$34) -> 29010.082 | T14: =S14/SUM($Q$5:$Q$34) -> 0.77661545 | U14: =IF(T14<=0.7,"A",IF(T14<=0.9,"B","C")) -> B | V14: =IF(D14<P14,"Reorder Now",IF(D14>M14*2,"Overstock","OK")) -> Overstock | W14: =IF(V14="Reorder Now",ROUND(MAX(M14,INDEX('Product Master'!$L$2:$L$31,MATCH($A14,'Product Master'!$A$2:$A$31,0))),0),0) -> 0
A15: ='Product Master'!A12 -> PH-011 | B15: ='Product Master'!B12 -> Insulin Glargine Injection | C15: ='Product Master'!C12 -> Antidiabetics | D15: =INDEX('Product Master'!$H$2:$H$31,MATCH($A15,'Product Master'!$A$2:$A$31,0)) -> 378 | E15: =INDEX('Product Master'!$F$2:$F$31,MATCH($A15,'Product Master'!$A$2:$A$31,0)) -> 17.38 | F15: =INDEX('Monthly Demand'!$O$2:$O$31,MATCH($A15,'Monthly Demand'!$A$2:$A$31,0)) -> 185 | G15: =INDEX('Monthly Demand'!$P$2:$P$31,MATCH($A15,'Monthly Demand'!$A$2:$A$31,0)) -> 15.416667 | H15: =INDEX('Monthly Demand'!$Q$2:$Q$31,MATCH($A15,'Monthly Demand'!$A$2:$A$31,0)) -> 1.2401124 | I15: =INDEX('Product Master'!$I$2:$I$31,MATCH($A15,'Product Master'!$A$2:$A$31,0)) -> 30 | J15: =INDEX('Product Master'!$J$2:$J$31,MATCH($A15,'Product Master'!$A$2:$A$31,0)) -> 268.63 | K15: =INDEX('Product Master'!$K$2:$K$31,MATCH($A15,'Product Master'!$A$2:$A$31,0)) -> 0.309 | L15: =E15*K15 -> 5.37042 | M15: =IFERROR(SQRT(2*F15*J15/L15),0) -> 136.04231 | N15: =F15/365 -> 0.50684932 | O15: =$B$2*H15*SQRT(I15/30) -> 2.0461855 | P15: =N15*I15+O15 -> 17.251665 | Q15: =D15*E15 -> 6569.64 | R15: =RANK(Q15,$Q$5:$Q$34) -> 2 | S15: =SUMPRODUCT(($R$5:$R$34<=R15)*$Q$5:$Q$34) -> 13946.884 | T15: =S15/SUM($Q$5:$Q$34) -> 0.37336557 | U15: =IF(T15<=0.7,"A",IF(T15<=0.9,"B","C")) -> A | V15: =IF(D15<P15,"Reorder Now",IF(D15>M15*2,"Overstock","OK")) -> Overstock | W15: =IF(V15="Reorder Now",ROUND(MAX(M15,INDEX('Product Master'!$L$2:$L$31,MATCH($A15,'Product Master'!$A$2:$A$31,0))),0),0) -> 0
A16: ='Product Master'!A13 -> PH-012 | B16: ='Product Master'!B13 -> Glimepiride 2mg Tablets | C16: ='Product Master'!C13 -> Antidiabetics | D16: =INDEX('Product Master'!$H$2:$H$31,MATCH($A16,'Product Master'!$A$2:$A$31,0)) -> 8068 | E16: =INDEX('Product Master'!$F$2:$F$31,MATCH($A16,'Product Master'!$A$2:$A$31,0)) -> 0.03 | F16: =INDEX('Monthly Demand'!$O$2:$O$31,MATCH($A16,'Monthly Demand'!$A$2:$A$31,0)) -> 6553 | G16: =INDEX('Monthly Demand'!$P$2:$P$31,MATCH($A16,'Monthly Demand'!$A$2:$A$31,0)) -> 546.08333 | H16: =INDEX('Monthly Demand'!$Q$2:$Q$31,MATCH($A16,'Monthly Demand'!$A$2:$A$31,0)) -> 38.77548 | I16: =INDEX('Product Master'!$I$2:$I$31,MATCH($A16,'Product Master'!$A$2:$A$31,0)) -> 30 | J16: =INDEX('Product Master'!$J$2:$J$31,MATCH($A16,'Product Master'!$A$2:$A$31,0)) -> 145.3 | K16: =INDEX('Product Master'!$K$2:$K$31,MATCH($A16,'Product Master'!$A$2:$A$31,0)) -> 0.22 | L16: =E16*K16 -> 0.0066 | M16: =IFERROR(SQRT(2*F16*J16/L16),0) -> 16986.188 | N16: =F16/365 -> 17.953425 | O16: =$B$2*H16*SQRT(I16/30) -> 63.979543 | P16: =N16*I16+O16 -> 602.58228 | Q16: =D16*E16 -> 242.04 | R16: =RANK(Q16,$Q$5:$Q$34) -> 23 | S16: =SUMPRODUCT(($R$5:$R$34<=R16)*$Q$5:$Q$34) -> 36767.023 | T16: =S16/SUM($Q$5:$Q$34) -> 0.98427293 | U16: =IF(T16<=0.7,"A",IF(T16<=0.9,"B","C")) -> C | V16: =IF(D16<P16,"Reorder Now",IF(D16>M16*2,"Overstock","OK")) -> OK | W16: =IF(V16="Reorder Now",ROUND(MAX(M16,INDEX('Product Master'!$L$2:$L$31,MATCH($A16,'Product Master'!$A$2:$A$31,0))),0),0) -> 0
... A34: ='Product Master'!A31 -> PH-030 | B34: ='Product Master'!B31 -> Hydrocortisone Cream 1% | C34: ='Product Master'!C31 -> Dermatological | D34: =INDEX('Product Master'!$H$2:$H$31,MATCH($A34,'Product Master'!$A$2:$A$31,0)) -> 608 | E34: =INDEX('Product Master'!$F$2:$F$31,MATCH($A34,'Product Master'!$A$2:$A$31,0)) -> 1.521 | F34: =INDEX('Monthly Demand'!$O$2:$O$31,MATCH($A34,'Monthly Demand'!$A$2:$A$31,0)) -> 698 | G34: =INDEX('Monthly Demand'!$P$2:$P$31,MATCH($A34,'Monthly Demand'!$A$2:$A$31,0)) -> 58.166667 | H34: =INDEX('Monthly Demand'!$Q$2:$Q$31,MATCH($A34,'Monthly Demand'!$A$2:$A$31,0)) -> 3.76185 | I34: =INDEX('Product Master'!$I$2:$I$31,MATCH($A34,'Product Master'!$A$2:$A$31,0)) -> 30 | J34: =INDEX('Product Master'!$J$2:$J$31,MATCH($A34,'Product Master'!$A$2:$A$31,0)) -> 77.54 | K34: =INDEX('Product Master'!$K$2:$K$31,MATCH($A34,'Product Master'!$A$2:$A$31,0)) -> 0.209 | L34: =E34*K34 -> 0.317889 | M34: =IFERROR(SQRT(2*F34*J34/L34),0) -> 583.53627 | N34: =F34/365 -> 1.9123288 | O34: =$B$2*H34*SQRT(I34/30) -> 6.2070524 | P34: =N34*I34+O34 -> 63.576915 | Q34: =D34*E34 -> 924.768 | R34: =RANK(Q34,$Q$5:$Q$34) -> 10 | S34: =SUMPRODUCT(($R$5:$R$34<=R34)*$Q$5:$Q$34) -> 29934.85 | T34: =S34/SUM($Q$5:$Q$34) -> 0.80137199 | U34: =IF(T34<=0.7,"A",IF(T34<=0.9,"B","C")) -> B | V34: =IF(D34<P34,"Reorder Now",IF(D34>M34*2,"Overstock","OK")) -> OK | W34: =IF(V34="Reorder Now",ROUND(MAX(M34,INDEX('Product Master'!$L$2:$L$31,MATCH($A34,'Product Master'!$A$2:$A$31,0))),0),0) -> 0

Sheet Expiry Tracker
A1: SKU ID | B1: Product Name | C1: Batch No. | D1: Manufacture Date | E1: Expiry Date | F1: Batch Quantity (Units) | G1: Days to Expiry | H1: Expiry Status
A2: PH-001 | B2: Paracetamol 500mg Tablets | C2: B001-1 | D2: 45970 | E2: 46255 | F2: 3838 | G2: =E2-TODAY() -> -15 | H2: =IF(G2<0,"Expired",IF(G2<=90,"Expiring Soon","OK")) -> Expired
A3: PH-002 | B3: Ibuprofen 400mg Tablets | C3: B002-1 | D3: 45779 | E3: 46859 | F3: 7545 | G3: =E3-TODAY() -> 589 | H3: =IF(G3<0,"Expired",IF(G3<=90,"Expiring Soon","OK")) -> OK
A4: PH-003 | B4: Aspirin 75mg Tablets | C4: B003-1 | D4: 45765 | E4: 46845 | F4: 76 | G4: =E4-TODAY() -> 575 | H4: =IF(G4<0,"Expired",IF(G4<=90,"Expiring Soon","OK")) -> OK
A5: PH-004 | B5: Diclofenac Gel 1% | C5: B004-1 | D5: 45556 | E5: 46636 | F5: 6228 | G5: =E5-TODAY() -> 366 | H5: =IF(G5<0,"Expired",IF(G5<=90,"Expiring Soon","OK")) -> OK
A6: PH-005 | B6: Amoxicillin 500mg Capsules | C6: B005-1 | D6: 45970 | E6: 46310 | F6: 1698 | G6: =E6-TODAY() -> 40 | H6: =IF(G6<0,"Expired",IF(G6<=90,"Expiring Soon","OK")) -> Expiring Soon
A7: PH-006 | B7: Azithromycin 250mg Tablets | C7: B006-1 | D7: 45908 | E7: 46808 | F7: 6221 | G7: =E7-TODAY() -> 538 | H7: =IF(G7<0,"Expired",IF(G7<=90,"Expiring Soon","OK")) -> OK
A8: PH-007 | B8: Ciprofloxacin 500mg Tablets | C8: B007-1 | D8: 46023 | E8: 46923 | F8: 3245 | G8: =E8-TODAY() -> 653 | H8: =IF(G8<0,"Expired",IF(G8<=90,"Expiring Soon","OK")) -> OK
A9: PH-008 | B9: Doxycycline 100mg Capsules | C9: B008-1 | D9: 45976 | E9: 46876 | F9: 4152 | G9: =E9-TODAY() -> 606 | H9: =IF(G9<0,"Expired",IF(G9<=90,"Expiring Soon","OK")) -> OK
A10: PH-009 | B10: Metronidazole 400mg Tablets | C10: B009-1 | D10: 45630 | E10: 46530 | F10: 56 | G10: =E10-TODAY() -> 260 | H10: =IF(G10<0,"Expired",IF(G10<=90,"Expiring Soon","OK")) -> OK
A11: PH-010 | B11: Metformin 500mg Tablets | C11: B010-1 | D11: 45958 | E11: 46678 | F11: 10322 | G11: =E11-TODAY() -> 408 | H11: =IF(G11<0,"Expired",IF(G11<=90,"Expiring Soon","OK")) -> OK
A12: PH-011 | B12: Insulin Glargine Injection | C12: B011-1 | D12: 45970 | E12: 46265 | F12: 368 | G12: =E12-TODAY() -> -5 | H12: =IF(G12<0,"Expired",IF(G12<=90,"Expiring Soon","OK")) -> Expired
A13: PH-012 | B13: Glimepiride 2mg Tablets | C13: B012-1 | D13: 46153 | E13: 46873 | F13: 5007 | G13: =E13-TODAY() -> 603 | H13: =IF(G13<0,"Expired",IF(G13<=90,"Expiring Soon","OK")) -> OK
... A41: PH-017 | B41: Oseltamivir 75mg Capsules | C41: B017-2 | D41: 46257 | E41: 46977 | F41: 1378 | G41: =E41-TODAY() -> 707 | H41: =IF(G41<0,"Expired",IF(G41<=90,"Expiring Soon","OK")) -> OK
